Workbook

Sheet INVENTARIO
A1: ITEM | B1: CODIGO | C1: TIPO CODIGO | D1: ALMACEN | E1: TIPO | F1: PRODUCTO | G1: MARCA | H1: MODELO | I1: UM | J1: STOCK | K1: MONEDA | L1: CU | M1: CP | N1: FECHA COMPRA | O1: ORIGEN | P1: ESTADO
A2: 1 | B2: F06227027162 | C2: FABRICA | D2: IMPORTADOS | E2: EQUIPO | F2: INVERSOR DE FRECUENCIA SOLAR HIBRIDO 2.2 KW MONOFASICO 220 V | G2: INVT | H2: GD100-2R2G-2-PV | I2: UND | J2: 92 | K2: DOLARES | L2: 60 | M2: =IF(OR(J2="",L2=""),"",ROUND(J2*L2,2)) | N2: 45958 | O2: EXCEL ORIGINAL | P2: =IF(OR(K2="",L2=""),"FALTA","OK")
A3: 2 | B3: @BBMO5B0100030013 | C3: FABRICA | D3: IMPORTADOS | E3: EQUIPO | F3: INVERSOR DE FRECUENCIA SOLAR HIBRIDO 5.5 KW MONOFASICO 220 V | G3: USFULL | H3: FU9000SI-5R5G-S2 | I3: UND | J3: 32 | K3: DOLARES | L3: 198 | M3: =IF(OR(J3="",L3=""),"",ROUND(J3*L3,2)) | N3: 45958 | O3: EXCEL ORIGINAL | P3: =IF(OR(K3="",L3=""),"FALTA","OK")
A4: 3 | B4: @BBMO5B0100040024 | C4: FABRICA | D4: IMPORTADOS | E4: EQUIPO | F4: INVERSOR DE FRECUENCIA SOLAR HIBRIDO 5.5 KW TRIFASICO 380 V | G4: USFULL | H4: FU9000SI-5R5G-9 | I4: UND | J4: 32 | K4: DOLARES | L4: 128 | M4: =IF(OR(J4="",L4=""),"",ROUND(J4*L4,2)) | N4: 45958 | O4: EXCEL ORIGINAL | P4: =IF(OR(K4="",L4=""),"FALTA","OK")
A5: 4 | B5: 6019241016168 | C5: FABRICA | D5: IMPORTADOS | E5: EQUIPO | F5: INVERSOR DE FRECUENCIA SOLAR HIBRIDO 11 KW TRIFASICO 380 V | G5: USFULL | H5: FU9000SI-011G-4 | I5: UND | J5: 28 | K5: DOLARES | L5: 170 | M5: =IF(OR(J5="",L5=""),"",ROUND(J5*L5,2)) | N5: 45958 | O5: EXCEL ORIGINAL | P5: =IF(OR(K5="",L5=""),"FALTA","OK")
A6: 5 | B6: @BBMO5B0100130006 | C6: FABRICA | D6: IMPORTADOS | E6: EQUIPO | F6: INVERSOR DE FRECUENCIA SOLAR HIBRIDO 22 KW TRIFASICO 380 V | G6: USFULL | H6: FU9000SI-022G-9 | I6: UND | J6: 6 | K6: DOLARES | L6: 303 | M6: =IF(OR(J6="",L6=""),"",ROUND(J6*L6,2)) | N6: 45958 | O6: EXCEL ORIGINAL | P6: =IF(OR(K6="",L6=""),"FALTA","OK")
A7: 6 | B7: @BBMO5B0100140002 | C7: FABRICA | D7: IMPORTADOS | E7: EQUIPO | F7: INVERSOR DE FRECUENCIA SOLAR HIBRIDO 55 KW TRIFASICO 380 V | G7: USFULL | H7: FU9000SI-055G-9 | I7: UND | J7: 5 | K7: DOLARES | L7: 650 | M7: =IF(OR(J7="",L7=""),"",ROUND(J7*L7,2)) | N7: 45958 | O7: EXCEL ORIGINAL | P7: =IF(OR(K7="",L7=""),"FALTA","OK")
A8: 7 | B8: @BBMO5B0100150004 | C8: FABRICA | D8: IMPORTADOS | E8: EQUIPO | F8: INVERSOR DE FRECUENCIA SOLAR HIBRIDO 75 KW TRIFASICO 380 V | G8: USFULL | H8: FU9000SI-075G-9 | I8: UND | J8: 4 | K8: DOLARES | L8: 850 | M8: =IF(OR(J8="",L8=""),"",ROUND(J8*L8,2)) | N8: 45958 | O8: EXCEL ORIGINAL | P8: =IF(OR(K8="",L8=""),"FALTA","OK")
A9: 8 | B9: @BBMO5B0100050003 | C9: FABRICA | D9: IMPORTADOS | E9: EQUIPO | F9: INVERSOR DE FRECUENCIA SOLAR HIBRIDO 110 KW TRIFASICO 380 V | G9: USFULL | H9: FU9000SI-110G-9 | I9: UND | J9: 5 | K9: DOLARES | L9: 1160 | M9: =IF(OR(J9="",L9=""),"",ROUND(J9*L9,2)) | N9: 45958 | O9: EXCEL ORIGINAL | P9: =IF(OR(K9="",L9=""),"FALTA","OK")
A10: 9 | B10: PROENERGIM-009 | C10: QR INTERNO | D10: IMPORTADOS | E10: EQUIPO | F10: INVERSOR DE FRECUENCIA SOLAR HIBRIDO 200 KW TRIFASICO 380 V | I10: UND | J10: 1 | K10: DOLARES | L10: 2070 | M10: =IF(OR(J10="",L10=""),"",ROUND(J10*L10,2)) | N10: 45958 | O10: EXCEL ORIGINAL | P10: =IF(OR(K10="",L10=""),"FALTA","OK")
A11: 10 | B11: NO 3010705523 | C11: FABRICA | D11: IMPORTADOS | E11: EQUIPO | F11: DISYUNTOR DE CC , 2 POLOS, 600V CC. 16 A | G11: USFULL | H11: FMB7N-63PV | I11: UND | J11: 360 | K11: DOLARES | L11: 4.4 | M11: =IF(OR(J11="",L11=""),"",ROUND(J11*L11,2)) | N11: 45958 | O11: EXCEL ORIGINAL | P11: =IF(OR(K11="",L11=""),"FALTA","OK")
A12: 11 | B12: 3014001058 | C12: FABRICA | D12: IMPORTADOS | E12: EQUIPO | F12: DISYUNTOR DE CAJA MOLDEADA DE CC, 2 POLOS, 320 A | G12: USFULL (prob.) | H12: FMM3-PV 320H 2P 320A | I12: UND | J12: 12 | K12: DOLARES | L12: 35.2 | M12: =IF(OR(J12="",L12=""),"",ROUND(J12*L12,2)) | N12: 45958 | O12: EXCEL ORIGINAL | P12: =IF(OR(K12="",L12=""),"FALTA","OK")
A13: 12 | B13: 3014001071 | C13: FABRICA | D13: IMPORTADOS | E13: EQUIPO | F13: DISYUNTOR DE CAJA MOLDEADA DE CC, 2 POLOS, 500 A | G13: USFULL (prob.) | H13: FMM3-PV 800H 2P 500A | I13: UND | J13: 12 | K13: DOLARES | L13: 59.1 | M13: =IF(OR(J13="",L13=""),"",ROUND(J13*L13,2)) | N13: 45958 | O13: EXCEL ORIGINAL | P13: =IF(OR(K13="",L13=""),"FALTA","OK")
A14: 13 | B14: 3014001074 | C14: FABRICA | D14: IMPORTADOS | E14: EQUIPO | F14: DISYUNTOR DE CAJA MOLDEADA DE CC, 2 POLOS, 800 A | G14: USFULL (prob.) | H14: FMM3-PV 800H 2P 800A | I14: UND | J14: 8 | K14: DOLARES | L14: 90.7 | M14: =IF(OR(J14="",L14=""),"",ROUND(J14*L14,2)) | N14: 45958 | O14: EXCEL ORIGINAL | P14: =IF(OR(K14="",L14=""),"FALTA","OK")
A15: 14 | B15: NO 3014003203 | C15: FABRICA | D15: IMPORTADOS | E15: EQUIPO | F15: SUPRESOR DE PICOS DE CC, 2 POLOS, 40 kA, 800 V CC | G15: USFULL | H15: FLY1-40PV T2 (2P) | I15: UND | J15: 120 | K15: DOLARES | L15: 3.9 | M15: =IF(OR(J15="",L15=""),"",ROUND(J15*L15,2)) | N15: 45958 | O15: EXCEL ORIGINAL | P15: =IF(OR(K15="",L15=""),"FALTA","OK")
A16: 15 | B16: PROENERGIM-015 | C16: QR INTERNO | D16: IMPORTADOS | E16: EQUIPO | F16: CONECTOR MC4 DE 6 MM 1000 V CC | I16: UND | J16: 1000 | K16: DOLARES | L16: 0.5 | M16: =IF(OR(J16="",L16=""),"",ROUND(J16*L16,2)) | N16: 45958 | O16: EXCEL ORIGINAL | P16: =IF(OR(K16="",L16=""),"FALTA","OK")
A17: 16 | B17: PROENERGIM-016 | C17: QR INTERNO | D17: IMPORTADOS | E17: EQUIPO | F17: Repuestos (2,2 kW, 5,5 kW, 11 kW) | G17: INVT (Goodrive) | H17: Modulos/Main Control Board/Power Panel | I17: UND | J17: 0.04 | K17: DOLARES | L17: 0.04 | M17: =IF(OR(J17="",L17=""),"",ROUND(J17*L17,2)) | N17: 45958 | O17: EXCEL ORIGINAL | P17: =IF(OR(K17="",L17=""),"FALTA","OK")
A18: 17 | B18: PROENERGIM-017 | C18: QR INTERNO | D18: LAS MERCEDES | E18: EPP | F18: CHALECO DRILL AMARILLO S-XL CON CINTA REFLECTIVA /BORDADO | I18: UND | J18: 50 | K18: SOLES | L18: 28 | M18: =IF(OR(J18="",L18=""),"",ROUND(J18*L18,2)) | N18: 45958 | O18: EXCEL ORIGINAL | P18: =IF(OR(K18="",L18=""),"FALTA","OK")
A19: 18 | B19: PROENERGIM-018 | C19: QR INTERNO | D19: LAS MERCEDES | E19: EPP | F19: GORRO DRILL SIN TAPANUCA CON BORDADO | I19: UND | J19: 50 | K19: SOLES | L19: 11 | M19: =IF(OR(J19="",L19=""),"",ROUND(J19*L19,2)) | N19: 45958 | O19: EXCEL ORIGINAL | P19: =IF(OR(K19="",L19=""),"FALTA","OK")
A20: 19 | B20: PROENERGIM-019 | C20: QR INTERNO | D20: LAS MERCEDES | E20: EPP | F20: SOMBRERO SAFARI DRILL TAPANUCA BEIGE | G20: - | H20: Logo Proenergim (sol+panel) | I20: UND | J20: 50 | K20: SOLES | L20: 4 | M20: =IF(OR(J20="",L20=""),"",ROUND(J20*L20,2)) | N20: 45967 | O20: EXCEL ORIGINAL | P20: =IF(OR(K20="",L20=""),"FALTA","OK")
A21: 20 | B21: (01)17799045023173 | C21: FABRICA | D21: LAS MERCEDES | E21: EPP | F21: GUANTEHILO AMARILLO STREELPRO | G21: STEELPRO SAFETY | H21: Multiflex | I21: UND | J21: 50 | K21: SOLES | L21: 2.92 | M21: =IF(OR(J21="",L21=""),"",ROUND(J21*L21,2)) | N21: 45958 | O21: EXCEL ORIGINAL | P21: =IF(OR(K21="",L21=""),"FALTA","OK")
A22: 21 | B22: 352451590099 | C22: FABRICA | D22: LAS MERCEDES | E22: EPP | F22: LENTES TRASNPARENTES LENTE SPY LUNA CLARA STEELPRO | G22: STEELPRO SAFETY | H22: SPY AF CLARO | I22: UND | J22: 50 | K22: SOLES | L22: 2.91 | M22: =IF(OR(J22="",L22=""),"",ROUND(J22*L22,2)) | N22: 45958 | O22: EXCEL ORIGINAL | P22: =IF(OR(K22="",L22=""),"FALTA","OK")
A23: 22 | B23: PROENERGIM-022 | C23: QR INTERNO | D23: LAS MERCEDES | E23: EPP | F23: TAPON AUDITIVOS AUDITIVO EN BOLSITA SEGLPRO | G23: SEGPRO | H23: Confort 2000 | I23: UND | J23: 100 | K23: SOLES | L23: 0.6 | M23: =IF(OR(J23="",L23=""),"",ROUND(J23*L23,2)) | N23: 45958 | O23: EXCEL ORIGINAL | P23: =IF(OR(K23="",L23=""),"FALTA","OK")
A24: 23 | B24: PROENERGIM-023 | C24: QR INTERNO | D24: LAS MERCEDES | E24: EPP | F24: MARCARILLA 7502 CON FILTRO 2097 ASA | I24: UND | J24: 3 | K24: SOLES | L24: 30 | M24: =IF(OR(J24="",L24=""),"",ROUND(J24*L24,2)) | N24: 45958 | O24: EXCEL ORIGINAL | P24: =IF(OR(K24="",L24=""),"FALTA","OK")
A25: 24 | B25: PROENERGIM-024 | C25: QR INTERNO | D25: LAS MERCEDES | E25: EPP | F25: CASCO JOCKEY STEELPRO AZUL | I25: UND | J25: 20 | K25: SOLES | L25: 15.5 | M25: =IF(OR(J25="",L25=""),"",ROUND(J25*L25,2)) | N25: 45958 | O25: EXCEL ORIGINAL | P25: =IF(OR(K25="",L25=""),"FALTA","OK")
A26: 25 | B26: PROENERGIM-025 | C26: QR INTERNO | D26: LAS MERCEDES | E26: EPP | F26: BLUSA OXFORD CELESTE TALLA L | I26: UND | J26: 3 | K26: SOLES | L26: 30 | M26: =IF(OR(J26="",L26=""),"",ROUND(J26*L26,2)) | N26: 45958 | O26: EXCEL ORIGINAL | P26: =IF(OR(K26="",L26=""),"FALTA","OK")
A27: 26 | B27: PROENERGIM-026 | C27: QR INTERNO | D27: LAS MERCEDES | E27: EPP | F27: POLO MANGA LARGA ESTAMPADO PECHO Y ESPALDA | I27: UND | J27: 50 | K27: SOLES | L27: 11 | M27: =IF(OR(J27="",L27=""),"",ROUND(J27*L27,2)) | N27: 45958 | O27: EXCEL ORIGINAL | P27: =IF(OR(K27="",L27=""),"FALTA","OK")
A28: 27 | B28: PROENERGIM-027 | C28: QR INTERNO | D28: LAS MERCEDES | E28: FERRETERIA | F28: ESCALERA MULTIUSO DE 12 PASOS | I28: UND | J28: 1 | K28: SOLES | L28: 530 | M28: =IF(OR(J28="",L28=""),"",ROUND(J28*L28,2)) | N28: 45982 | O28: EXCEL ORIGINAL | P28: =IF(OR(K28="",L28=""),"FALTA","OK")
A29: 28 | B29: PROENERGIM-028 | C29: QR INTERNO | D29: LAS MERCEDES | E29: FERRETERIA | F29: ESCALERA MULTIUSO DE 24 PASOS | I29: UND | J29: 1 | K29: SOLES | L29: 820 | M29: =IF(OR(J29="",L29=""),"",ROUND(J29*L29,2)) | N29: 45982 | O29: EXCEL ORIGINAL | P29: =IF(OR(K29="",L29=""),"FALTA","OK")
A30: 29 | B30: PROENERGIM-029 | C30: QR INTERNO | D30: LAS MERCEDES | E30: FERRETERIA | F30: PERNOS DE DOS GROSORES DOS CAJAS | I30: UND | J30: 2 | K30: SOLES | M30: =IF(OR(J30="",L30=""),"",ROUND(J30*L30,2)) | O30: EXCEL ORIGINAL | P30: =IF(OR(K30="",L30=""),"FALTA","OK")
A31: 30 | B31: PROENERGIM-030 | C31: QR INTERNO | D31: LAS MERCEDES | E31: FERRETERIA | F31: CODO CLASE 10 CON ROSCA | I31: UND | J31: 2 | M31: =IF(OR(J31="",L31=""),"",ROUND(J31*L31,2)) | O31: EXCEL ORIGINAL | P31: =IF(OR(K31="",L31=""),"FALTA","OK")
A32: 31 | B32: PROENERGIM-031 | C32: QR INTERNO | D32: LAS MERCEDES | E32: FERRETERIA | F32: CODO | I32: UND | J32: 2 | M32: =IF(OR(J32="",L32=""),"",ROUND(J32*L32,2)) | O32: EXCEL ORIGINAL | P32: =IF(OR(K32="",L32=""),"FALTA","OK")
A33: 32 | B33: PROENERGIM-032 | C33: QR INTERNO | D33: LAS MERCEDES | E33: FERRETERIA | F33: VARIADOR - LAS MERCEDES | I33: UND | J33: 2 | M33: =IF(OR(J33="",L33=""),"",ROUND(J33*L33,2)) | O33: EXCEL ORIGINAL | P33: =IF(OR(K33="",L33=""),"FALTA","OK")
A34: 33 | B34: PROENERGIM-033 | C34: QR INTERNO | D34: LAS MERCEDES | E34: FERRETERIA | F34: CODOS | I34: UND | J34: 1 | M34: =IF(OR(J34="",L34=""),"",ROUND(J34*L34,2)) | O34: EXCEL ORIGINAL | P34: =IF(OR(K34="",L34=""),"FALTA","OK")
A35: 34 | B35: PROENERGIM-034 | C35: QR INTERNO | D35: LAS MERCEDES | E35: FERRETERIA | F35: CODITO | I35: UND | J35: 3 | M35: =IF(OR(J35="",L35=""),"",ROUND(J35*L35,2)) | O35: EXCEL ORIGINAL | P35: =IF(OR(K35="",L35=""),"FALTA","OK")
A36: 35 | B36: PROENERGIM-035 | C36: QR INTERNO | D36: LAS MERCEDES | E36: FERRETERIA | F36: CODO | I36: UND | J36: 1 | M36: =IF(OR(J36="",L36=""),"",ROUND(J36*L36,2)) | O36: EXCEL ORIGINAL | P36: =IF(OR(K36="",L36=""),"FALTA","OK")
A37: 36 | B37: PROENERGIM-036 | C37: QR INTERNO | D37: LAS MERCEDES | E37: FERRETERIA | F37: PEGAMENTO | I37: UND | J37: 1 | M37: =IF(OR(J37="",L37=""),"",ROUND(J37*L37,2)) | O37: EXCEL ORIGINAL | P37: =IF(OR(K37="",L37=""),"FALTA","OK")
A38: 37 | B38: PROENERGIM-037 | C38: QR INTERNO | D38: LAS MERCEDES | E38: FERRETERIA | F38: CODO | I38: UND | J38: 1 | M38: =IF(OR(J38="",L38=""),"",ROUND(J38*L38,2)) | O38: EXCEL ORIGINAL | P38: =IF(OR(K38="",L38=""),"FALTA","OK")
A39: 38 | B39: PROENERGIM-038 | C39: QR INTERNO | D39: LAS MERCEDES | E39: FERRETERIA | F39: VENTILADOR - LAS MERCEDES | I39: UND | J39: 1 | M39: =IF(OR(J39="",L39=""),"",ROUND(J39*L39,2)) | O39: EXCEL ORIGINAL | P39: =IF(OR(K39="",L39=""),"FALTA","OK")
A40: 39 | B40: PROENERGIM-039 | C40: QR INTERNO | D40: ALMACEN 2 | E40: EPP | F40: PONCHOS | I40: UND | J40: 1 | M40: =IF(OR(J40="",L40=""),"",ROUND(J40*L40,2)) | O40: EXCEL ORIGINAL | P40: =IF(OR(K40="",L40=""),"FALTA","OK")
...

Sheet RESUMEN
A1: RESUMEN DE COSTOS — bd_v2
A3: Productos totales | B3: =COUNTA(INVENTARIO!A2:A133)
A4: del Excel original | B4: =COUNTIF(INVENTARIO!O2:O133,"EXCEL ORIGINAL")
A5: nuevos (hallados en las fotos) | B5: =COUNTIF(INVENTARIO!O2:O133,"NUEVO (FOTOS)")
A7: Con costo cargado | B7: =COUNTIF(INVENTARIO!P2:P133,"OK")
A8: FALTA costo o moneda | B8: =COUNTIF(INVENTARIO!P2:P133,"FALTA")
A10: VALORIZADO (solo lo que ya tiene costo)
A11: Total en DOLARES | B11: =SUMIF(INVENTARIO!K2:K133,"DOLARES",INVENTARIO!M2:M133)
A12: Total en SOLES | B12: =SUMIF(INVENTARIO!K2:K133,"SOLES",INVENTARIO!M2:M133)
A14: POR ALMACEN | B14: Productos | C14: Con costo | D14: Falta
A15: IMPORTADOS | B15: =COUNTIF(INVENTARIO!D2:D133,"IMPORTADOS") | C15: =COUNTIFS(INVENTARIO!D2:D133,"IMPORTADOS",INVENTARIO!P2:P133,"OK") | D15: =COUNTIFS(INVENTARIO!D2:D133,"IMPORTADOS",INVENTARIO!P2:P133,"FALTA")
A16: LAS MERCEDES | B16: =COUNTIF(INVENTARIO!D2:D133,"LAS MERCEDES") | C16: =COUNTIFS(INVENTARIO!D2:D133,"LAS MERCEDES",INVENTARIO!P2:P133,"OK") | D16: =COUNTIFS(INVENTARIO!D2:D133,"LAS MERCEDES",INVENTARIO!P2:P133,"FALTA")
A17: ALMACEN 2 | B17: =COUNTIF(INVENTARIO!D2:D133,"ALMACEN 2") | C17: =COUNTIFS(INVENTARIO!D2:D133,"ALMACEN 2",INVENTARIO!P2:P133,"OK") | D17: =COUNTIFS(INVENTARIO!D2:D133,"ALMACEN 2",INVENTARIO!P2:P133,"FALTA")
A18: POR DEFINIR | B18: =COUNTIF(INVENTARIO!D2:D133,"POR DEFINIR") | C18: =COUNTIFS(INVENTARIO!D2:D133,"POR DEFINIR",INVENTARIO!P2:P133,"OK") | D18: =COUNTIFS(INVENTARIO!D2:D133,"POR DEFINIR",INVENTARIO!P2:P133,"FALTA")
A21: COMO COMPLETARLO
A22: • Las celdas AMARILLAS son las que hay que llenar: MONEDA, CU y, en los nuevos, ALMACEN y STOCK.
A23: • CP y ESTADO se calculan solos con formula: no los edites.
A24: • ALMACEN, TIPO y MONEDA tienen lista desplegable.
A25: • Los ITEM con fondo NARANJA traen datos raros del Excel original: mira la hoja REVISAR.
A26: • Los productos con fondo VERDE son los 10 que no estaban en el Excel y si estan en la base.
A27: • No sumes DOLARES con SOLES: por eso el valorizado esta separado por moneda.

Sheet REVISAR
A1: ITEM | B1: PRODUCTO | C1: QUE PASA
A2: 16 | B2: Repuestos (2,2 kW, 5,5 kW, 11 kW) | C2: STOCK 0.04 y CP 4.00 no cuadran con CU 0.04: las columnas parecen corridas en el origen
A3: 29 | B3: PERNOS DE DOS GROSORES DOS CAJAS | C3: sin unidad de medida (UM) en el Excel original
A4: 72 | B4: PUNTERAS | C4: sin STOCK en el Excel original
A5: 74 | B5: NIVEL DE MANO | C5: la MONEDA decia "NO SIRVE" (parece el estado del equipo, no una moneda)
A6: 78 | B6: SOGA | C6: sin STOCK en el Excel original
